#VRML_SIM R2020a utf8
WorldInfo {
  contactProperties [
    ContactProperties {
      material2 "slider"
      coulombFriction [
        0
      ]
    }
  ]
}
Viewpoint {
  orientation -0.661945786941256 -0.7269816964106661 -0.18255242598933405 0.72516028463655
  position -0.48925558774892863 0.5544096777298615 0.9517355365552884
}
TexturedBackground {
}
TexturedBackgroundLight {
}
RectangleArena {
  floorTileSize 1 1
  floorAppearance PBRAppearance {
    baseColorMap ImageTexture {
      url [
        "textures/robot_floor_texture.png"
      ]
    }
    roughness 1
    metalness 0
  }
}
Robot {
  children [
    DEF BODY_TR Transform {
      translation 0 0.04 0
      children [
        Shape {
          appearance DEF BODY_APR PBRAppearance {
            baseColor 1 0 0
            roughness 1
            metalness 0
          }
          geometry DEF BODY Box {
            size 0.08 0.04 0.15
          }
        }
      ]
    }
    Solid {
      translation 0 0.02 -0.05
      rotation 0 0 1 1.5707996938995747
      children [
        DEF CASTOR Shape {
          appearance PBRAppearance {
            baseColor 0 1 1
          }
          geometry Sphere {
            radius 0.02
          }
        }
      ]
      contactMaterial "slider"
      boundingObject USE CASTOR
      physics Physics {
      }
    }
    DEF IDLER_TR Transform {
      translation 0 0.02 -0.05
      rotation 0 0 1 1.5707996938995747
      children [
        Shape {
          appearance PBRAppearance {
            baseColor 0 1 1
          }
          geometry DEF IDLER_BODY Sphere {
            radius 0.02
          }
        }
      ]
    }
    DEF CAM_MOUNT_TR Transform {
      translation 0 0.06 0.075
      rotation 0 0 1 1.5707996938995747
      children [
        Shape {
          appearance USE BODY_APR
          geometry DEF CAM_MOUNT Capsule {
            height 0.02
            radius 0.01
          }
        }
      ]
    }
    HingeJoint {
      jointParameters HingeJointParameters {
        anchor 0 0.03 0.04
      }
      device [
        RotationalMotor {
          name "left wheel motor"
          consumptionFactor 70
          maxVelocity 8
        }
        PositionSensor {
          name "left wheel encoder"
        }
      ]
      endPoint Solid {
        translation 0.04544579699778018 0.029921197509671357 0.03990746245182779
        rotation 0.653567359805034 0.7494675479174239 -0.10558456713043349 6.266557882961011
        children [
          DEF R2_WHEEL Transform {
            rotation 0 0 1 1.57
            children [
              Shape {
                appearance PBRAppearance {
                  baseColor 0 1 0
                  roughness 1
                  metalness 0
                }
                geometry Cylinder {
                  height 0.01
                  radius 0.03
                }
              }
            ]
          }
        ]
        name "left wheel"
        boundingObject USE R2_WHEEL
        physics DEF R2_PHYSICS_WHEEL Physics {
          density -1
          mass 0.05
        }
      }
    }
    HingeJoint {
      jointParameters HingeJointParameters {
        anchor 0 0.03 0.04
      }
      device [
        RotationalMotor {
          name "right wheel motor"
          consumptionFactor 70
          maxVelocity 8
        }
        PositionSensor {
          name "right wheel encoder"
        }
      ]
      endPoint Solid {
        translation -0.04527154148080561 0.029375422536435217 0.03972129334266368
        rotation -0.9999644575432618 -0.004621651719257443 -0.0070515236364891275 1.6849974077044423
        children [
          USE R2_WHEEL
        ]
        name "right wheel"
        boundingObject USE R2_WHEEL
        physics USE R2_PHYSICS_WHEEL
      }
    }
    DistanceSensor {
      translation 0.025 0.04 0.072
      rotation 0 1 0 -1.1781003061004252
      children [
        DEF R2_SENSOR Transform {
          rotation 0 0 1 1.5699996938995748
          children [
            Shape {
              appearance PBRAppearance {
                baseColor 0.975691 0.981481 0.0252992
                roughness 1
                metalness 0
              }
              geometry Box {
                size 0.01 0.01 0.01
              }
            }
          ]
        }
      ]
      name "ds0"
      lookupTable [
        0 1024 0
        0.05 1024 0
        0.15 0 0
      ]
      numberOfRays 2
      aperture 1
    }
    DistanceSensor {
      translation -0.025 0.04 0.072
      rotation 0 1 0 -1.9634996938995748
      children [
        USE R2_SENSOR
      ]
      name "ds1"
      lookupTable [
        0 1024 0
        0.05 1024 0
        0.15 0 0
      ]
      numberOfRays 2
      aperture 1
    }
    Camera {
      translation 0 0.07 0.09
      rotation 0 1 0 3.141592653589793
      children [
        Transform {
          translation 0 0 0.015
          rotation 1 0 0 1.57
          children [
            Shape {
              appearance PBRAppearance {
                roughness 1
                metalness 0
              }
              geometry Cylinder {
                height 0.03
                radius 0.01
              }
            }
          ]
        }
      ]
      fieldOfView 1.047
      width 400
      height 300
      antiAliasing TRUE
      noise 0.04
    }
    Compass {
      translation 0 0.04 0
      yAxis FALSE
      zAxis FALSE
    }
  ]
  name "TheEgg-zecutive"
  contactMaterial ""
  boundingObject Group {
    children [
      USE BODY_TR
      USE CAM_MOUNT_TR
    ]
  }
  physics Physics {
    density -1
    mass 0.5
  }
  controller "basic_obstacle_avoidance"
}
