#VRML_SIM R2020a utf8
WorldInfo {
  contactProperties [
    ContactProperties {
      material2 "slider"
      coulombFriction [
        0
      ]
    }
  ]
}
Viewpoint {
  orientation -0.661945786941256 -0.7269816964106661 -0.18255242598933405 0.72516028463655
  position -0.48925558774892863 0.5544096777298615 0.9517355365552884
}
TexturedBackground {
}
TexturedBackgroundLight {
}
RectangleArena {
  floorTileSize 1 1
  floorAppearance PBRAppearance {
    baseColorMap ImageTexture {
      url [
        "textures/robot_floor_texture.png"
      ]
    }
    roughness 1
    metalness 0
  }
}
Robot {
  children [
    DEF BASE_TR Transform {
      translation 0 0.03 0
      children [
        Shape {
          appearance DEF BODY_ARP PBRAppearance {
            baseColor 0 1 0
            roughness 1
            metalness 0
          }
          geometry DEF BASE Box {
            size 0.07 0.04 0.12
          }
        }
      ]
    }
    DEF TOP_TR Transform {
      translation 0 0.06 0
      children [
        Shape {
          appearance USE BODY_ARP
          geometry DEF TOP Cylinder {
            height 0.02
            radius 0.07
          }
        }
      ]
    }
    DEF LEFT_IDLER Solid {
      translation 0.04 0.024 -0.04
      rotation 0 0 1 1.5707996938995747
      children [
        DEF IDLER Shape {
          appearance PBRAppearance {
            baseColor 0.5 0.5 0.5
            roughness 1
            metalness 0
          }
          geometry Cylinder {
            height 0.01
            radius 0.024
          }
        }
      ]
      contactMaterial "slider"
      boundingObject USE IDLER
      physics Physics {
      }
    }
    DEF RIGHT_IDLER Solid {
      translation -0.04 0.024 -0.04
      rotation 0 0 1 1.5707996938995747
      children [
        USE IDLER
      ]
      name "solid(1)"
      contactMaterial "slider"
      boundingObject USE IDLER
      physics Physics {
      }
    }
    HingeJoint {
      jointParameters HingeJointParameters {
        anchor 0 0.024 0.04
      }
      device [
        RotationalMotor {
          name "left wheel motor"
          consumptionFactor 70
          maxVelocity 8
        }
        PositionSensor {
          name "left wheel encoder"
        }
      ]
      endPoint Solid {
        translation 0.04 0.024 0.04
        rotation -1 0 0 0
        children [
          DEF R3_WHEEL Transform {
            rotation 0 0 1 1.57
            children [
              Shape {
                appearance PBRAppearance {
                  baseColor 0 0 1
                  roughness 1
                  metalness 0
                }
                geometry Cylinder {
                  height 0.01
                  radius 0.024
                }
              }
            ]
          }
        ]
        name "left wheel"
        boundingObject USE R3_WHEEL
        physics DEF R3_PHYSICS_WHEEL Physics {
          density -1
          mass 0.05
        }
      }
    }
    HingeJoint {
      jointParameters HingeJointParameters {
        anchor 0 0.024 0.04
      }
      device [
        RotationalMotor {
          name "right wheel motor"
          consumptionFactor 70
          maxVelocity 8
        }
        PositionSensor {
          name "right wheel encoder"
        }
      ]
      endPoint Solid {
        translation -0.04 0.024 0.04
        rotation 1 0 0 4.58735
        children [
          USE R3_WHEEL
        ]
        name "right wheel"
        boundingObject USE R3_WHEEL
        physics USE R3_PHYSICS_WHEEL
      }
    }
    DistanceSensor {
      translation 0.03 0.06 0.06
      rotation 0 1 0 -1.1781003061004252
      children [
        DEF R3_SENSOR Transform {
          rotation 0 0 1 1.5699996938995748
          children [
            Shape {
              appearance PBRAppearance {
                baseColor 0.975691 0.981481 0.0252992
                roughness 1
                metalness 0
              }
              geometry Box {
                size 0.01 0.01 0.01
              }
            }
          ]
        }
      ]
      name "ds0"
      lookupTable [
        0 1024 0
        0.05 1024 0
        0.15 0 0
      ]
      numberOfRays 2
      aperture 1
    }
    DistanceSensor {
      translation -0.03 0.06 0.06
      rotation 0 1 0 -1.9634996938995748
      children [
        USE R3_SENSOR
      ]
      name "ds1"
      lookupTable [
        0 1024 0
        0.05 1024 0
        0.15 0 0
      ]
      numberOfRays 2
      aperture 1
    }
    Camera {
      translation 0 0.06 0.08
      rotation 0 1 0 3.141592653589793
      children [
        Transform {
          translation 0 0 0.015
          rotation 1 0 0 1.57
          children [
            Shape {
              appearance PBRAppearance {
                roughness 1
                metalness 0
              }
              geometry Cylinder {
                height 0.03
                radius 0.01
              }
            }
          ]
        }
      ]
      fieldOfView 1.047
      width 400
      height 300
      antiAliasing TRUE
      noise 0.04
    }
    Compass {
      translation 0 0.04 0
      yAxis FALSE
      zAxis FALSE
    }
  ]
  name "TheEgg-sterminator"
  contactMaterial ""
  boundingObject Group {
    children [
      USE BASE_TR
      USE TOP_TR
    ]
  }
  physics Physics {
    density -1
    mass 0.5
  }
  controller "basic_obstacle_avoidance"
}
